Finished writing file
1.4776835 0.5877828
107.92.121.189 - - [29/Nov/2018 22:14:15] "[37mPOST /upload HTTP/1.1[0m" 200 -
Finished writing file
1.0776867 0.98735094
107.92.121.189 - - [29/Nov/2018 22:14:19] "[37mPOST /upload HTTP/1.1[0m" 200 -
Finished writing file
1.1895952 0.873732
107.92.121.189 - - [29/Nov/2018 22:14:24] "[37mPOST /upload HTTP/1.1[0m" 200 -
Finished writing file
2.6719797 -0.60577655
107.92.121.189 - - [29/Nov/2018 22:14:28] "[37mPOST /upload HTTP/1.1[0m" 200 -
Finished writing file
1.5803058 0.48603714
107.92.121.189 - - [29/Nov/2018 22:14:34] "[37mPOST /upload HTTP/1.1[0m" 200 -
Finished writing file
0.8778481 1.1847286
107.92.121.189 - - [29/Nov/2018 22:14:40] "[37mPOST /upload HTTP/1.1[0m" 200 -
Finished writing file
1.4431794 0.62095183
107.92.121.189 - - [29/Nov/2018 22:14:45] "[37mPOST /upload HTTP/1.1[0m" 200 -
Finished writing file
2.9657702 -0.8987144
107.92.121.189 - - [29/Nov/2018 22:14:50] "[37mPOST /upload HTTP/1.1[0m" 200 -
Finished writing file
1.1302133 0.9349619
107.92.121.189 - - [29/Nov/2018 22:14:56] "[37mPOST /upload HTTP/1.1[0m" 200 -
Finished writing file
1.9110942 0.15141761
107.92.121.189 - - [29/Nov/2018 22:15:02] "[37mPOST /upload HTTP/1.1[0m" 200 -
2018-11-29-22-14-46
2018-11-29-22-14-52
2018-11-29-22-14-58
107.92.121.189 - - [29/Nov/2018 22:16:20] "[37mGET /getFiles/2 HTTP/1.1[0m" 200 -
2018-11-29-22-14-46
2018-11-29-22-14-52
2018-11-29-22-14-58
107.92.121.189 - - [29/Nov/2018 22:16:20] "[37mGET /getFiles/2 HTTP/1.1[0m" 200 -
2018-11-29-22-14-46
2018-11-29-22-14-52
2018-11-29-22-14-58
107.92.121.189 - - [29/Nov/2018 22:16:30] "[37mGET /getFiles/2 HTTP/1.1[0m" 200 -
2018-11-29-22-14-46
2018-11-29-22-14-52
2018-11-29-22-14-58
107.92.121.189 - - [29/Nov/2018 22:16:31] "[37mGET /getFiles/2 HTTP/1.1[0m" 200 -
Error on request:
Traceback (most recent call last):
  File "/opt/anaconda2/lib/python2.7/site-packages/werkzeug/serving.py", line 270, in run_wsgi
    execute(self.server.app)
  File "/opt/anaconda2/lib/python2.7/site-packages/werkzeug/serving.py", line 261, in execute
    write(data)
  File "/opt/anaconda2/lib/python2.7/site-packages/werkzeug/serving.py", line 242, in write
    self.wfile.write(data)
IOError: [Errno 104] Connection reset by peer
Error on request:
Traceback (most recent call last):
  File "/opt/anaconda2/lib/python2.7/site-packages/werkzeug/serving.py", line 270, in run_wsgi
    execute(self.server.app)
  File "/opt/anaconda2/lib/python2.7/site-packages/werkzeug/serving.py", line 261, in execute
    write(data)
  File "/opt/anaconda2/lib/python2.7/site-packages/werkzeug/serving.py", line 242, in write
    self.wfile.write(data)
IOError: [Errno 104] Connection reset by peer
2018-11-29-22-05-21
2018-11-29-22-07-28
2018-11-29-22-07-34
2018-11-29-22-14-11
2018-11-29-22-14-16
2018-11-29-22-14-20
2018-11-29-22-14-24
2018-11-29-22-14-30
2018-11-29-22-14-36
2018-11-29-22-14-41
107.92.121.189 - - [29/Nov/2018 22:17:26] "[37mGET /getFiles/1 HTTP/1.1[0m" 200 -
2018-11-29-22-05-21
2018-11-29-22-07-28
2018-11-29-22-07-34
2018-11-29-22-14-11
2018-11-29-22-14-16
2018-11-29-22-14-20
2018-11-29-22-14-24
2018-11-29-22-14-30
2018-11-29-22-14-36
2018-11-29-22-14-41
107.92.121.189 - - [29/Nov/2018 22:17:26] "[37mGET /getFiles/1 HTTP/1.1[0m" 200 -
2018-11-29-22-05-21
2018-11-29-22-07-28
2018-11-29-22-07-34
2018-11-29-22-14-11
2018-11-29-22-14-16
2018-11-29-22-14-20
2018-11-29-22-14-24
2018-11-29-22-14-30
2018-11-29-22-14-36
2018-11-29-22-14-41
107.92.121.189 - - [29/Nov/2018 22:17:42] "[37mGET /getFiles/1 HTTP/1.1[0m" 200 -
2018-11-29-22-05-21
2018-11-29-22-07-28
2018-11-29-22-07-34
2018-11-29-22-14-11
2018-11-29-22-14-16
2018-11-29-22-14-20
2018-11-29-22-14-24
2018-11-29-22-14-30
2018-11-29-22-14-36
2018-11-29-22-14-41
107.92.121.189 - - [29/Nov/2018 22:17:42] "[37mGET /getFiles/1 HTTP/1.1[0m" 200 -
Error on request:
Traceback (most recent call last):
  File "/opt/anaconda2/lib/python2.7/site-packages/werkzeug/serving.py", line 270, in run_wsgi
    execute(self.server.app)
  File "/opt/anaconda2/lib/python2.7/site-packages/werkzeug/serving.py", line 261, in execute
    write(data)
  File "/opt/anaconda2/lib/python2.7/site-packages/werkzeug/serving.py", line 242, in write
    self.wfile.write(data)
IOError: [Errno 104] Connection reset by peer
Error on request:
Traceback (most recent call last):
  File "/opt/anaconda2/lib/python2.7/site-packages/werkzeug/serving.py", line 270, in run_wsgi
    execute(self.server.app)
  File "/opt/anaconda2/lib/python2.7/site-packages/werkzeug/serving.py", line 261, in execute
    write(data)
  File "/opt/anaconda2/lib/python2.7/site-packages/werkzeug/serving.py", line 242, in write
    self.wfile.write(data)
IOError: [Errno 104] Connection reset by peer
2018-11-29-22-05-21
2018-11-29-22-07-28
2018-11-29-22-07-34
2018-11-29-22-14-11
2018-11-29-22-14-16
2018-11-29-22-14-20
2018-11-29-22-14-24
2018-11-29-22-14-30
2018-11-29-22-14-36
2018-11-29-22-14-41
107.92.121.189 - - [29/Nov/2018 22:19:08] "[37mGET /getFiles/1 HTTP/1.1[0m" 200 -
2018-11-29-22-05-21
2018-11-29-22-07-28
2018-11-29-22-07-34
2018-11-29-22-14-11
2018-11-29-22-14-16
2018-11-29-22-14-20
2018-11-29-22-14-24
2018-11-29-22-14-30
2018-11-29-22-14-36
2018-11-29-22-14-41
107.92.121.189 - - [29/Nov/2018 22:19:08] "[37mGET /getFiles/1 HTTP/1.1[0m" 200 -
Error on request:
Traceback (most recent call last):
  File "/opt/anaconda2/lib/python2.7/site-packages/werkzeug/serving.py", line 270, in run_wsgi
    execute(self.server.app)
  File "/opt/anaconda2/lib/python2.7/site-packages/werkzeug/serving.py", line 261, in execute
    write(data)
  File "/opt/anaconda2/lib/python2.7/site-packages/werkzeug/serving.py", line 242, in write
    self.wfile.write(data)
IOError: [Errno 104] Connection reset by peer
2018-11-29-22-05-21
2018-11-29-22-07-28
2018-11-29-22-07-34
2018-11-29-22-14-11
2018-11-29-22-14-16
2018-11-29-22-14-20
2018-11-29-22-14-24
2018-11-29-22-14-30
2018-11-29-22-14-36
2018-11-29-22-14-41
107.92.121.189 - - [29/Nov/2018 22:21:17] "[37mGET /getFiles/1 HTTP/1.1[0m" 200 -
2018-11-29-22-05-21
2018-11-29-22-07-28
2018-11-29-22-07-34
2018-11-29-22-14-11
2018-11-29-22-14-16
2018-11-29-22-14-20
2018-11-29-22-14-24
2018-11-29-22-14-30
2018-11-29-22-14-36
2018-11-29-22-14-41
107.92.121.189 - - [29/Nov/2018 22:21:17] "[37mGET /getFiles/1 HTTP/1.1[0m" 200 -
Error on request:
Traceback (most recent call last):
  File "/opt/anaconda2/lib/python2.7/site-packages/werkzeug/serving.py", line 270, in run_wsgi
    execute(self.server.app)
  File "/opt/anaconda2/lib/python2.7/site-packages/werkzeug/serving.py", line 261, in execute
    write(data)
  File "/opt/anaconda2/lib/python2.7/site-packages/werkzeug/serving.py", line 242, in write
    self.wfile.write(data)
IOError: [Errno 104] Connection reset by peer
2018-11-29-22-05-21
2018-11-29-22-07-28
2018-11-29-22-07-34
2018-11-29-22-14-11
2018-11-29-22-14-16
2018-11-29-22-14-20
2018-11-29-22-14-24
2018-11-29-22-14-30
2018-11-29-22-14-36
2018-11-29-22-14-41
107.92.121.189 - - [29/Nov/2018 22:23:13] "[37mGET /getFiles/1 HTTP/1.1[0m" 200 -
2018-11-29-22-05-21
2018-11-29-22-07-28
2018-11-29-22-07-34
2018-11-29-22-14-11
2018-11-29-22-14-16
2018-11-29-22-14-20
2018-11-29-22-14-24
2018-11-29-22-14-30
2018-11-29-22-14-36
2018-11-29-22-14-41
107.92.121.189 - - [29/Nov/2018 22:23:13] "[37mGET /getFiles/1 HTTP/1.1[0m" 200 -
Error on request:
Traceback (most recent call last):
  File "/opt/anaconda2/lib/python2.7/site-packages/werkzeug/serving.py", line 270, in run_wsgi
    execute(self.server.app)
  File "/opt/anaconda2/lib/python2.7/site-packages/werkzeug/serving.py", line 261, in execute
    write(data)
  File "/opt/anaconda2/lib/python2.7/site-packages/werkzeug/serving.py", line 242, in write
    self.wfile.write(data)
IOError: [Errno 104] Connection reset by peer
2018-11-29-22-05-21
2018-11-29-22-07-28
2018-11-29-22-07-34
2018-11-29-22-14-11
2018-11-29-22-14-16
2018-11-29-22-14-20
2018-11-29-22-14-24
2018-11-29-22-14-30
2018-11-29-22-14-36
2018-11-29-22-14-41
107.92.121.189 - - [29/Nov/2018 22:25:09] "[37mGET /getFiles/1 HTTP/1.1[0m" 200 -
2018-11-29-22-05-21
2018-11-29-22-07-28
2018-11-29-22-07-34
2018-11-29-22-14-11
2018-11-29-22-14-16
2018-11-29-22-14-20
2018-11-29-22-14-24
2018-11-29-22-14-30
2018-11-29-22-14-36
2018-11-29-22-14-41
107.92.121.189 - - [29/Nov/2018 22:25:09] "[37mGET /getFiles/1 HTTP/1.1[0m" 200 -
Error on request:
Traceback (most recent call last):
  File "/opt/anaconda2/lib/python2.7/site-packages/werkzeug/serving.py", line 270, in run_wsgi
    execute(self.server.app)
  File "/opt/anaconda2/lib/python2.7/site-packages/werkzeug/serving.py", line 261, in execute
    write(data)
  File "/opt/anaconda2/lib/python2.7/site-packages/werkzeug/serving.py", line 242, in write
    self.wfile.write(data)
IOError: [Errno 32] Broken pipe
2018-11-29-22-05-21
2018-11-29-22-07-28
2018-11-29-22-07-34
2018-11-29-22-14-11
2018-11-29-22-14-16
2018-11-29-22-14-20
2018-11-29-22-14-24
2018-11-29-22-14-30
2018-11-29-22-14-36
2018-11-29-22-14-41
107.92.121.189 - - [29/Nov/2018 22:25:13] "[37mGET /getFiles/1 HTTP/1.1[0m" 200 -
2018-11-29-22-05-21
2018-11-29-22-07-28
2018-11-29-22-07-34
2018-11-29-22-14-11
2018-11-29-22-14-16
2018-11-29-22-14-20
2018-11-29-22-14-24
2018-11-29-22-14-30
2018-11-29-22-14-36
2018-11-29-22-14-41
107.92.121.189 - - [29/Nov/2018 22:25:13] "[37mGET /getFiles/1 HTTP/1.1[0m" 200 -
Error on request:
Traceback (most recent call last):
  File "/opt/anaconda2/lib/python2.7/site-packages/werkzeug/serving.py", line 270, in run_wsgi
    execute(self.server.app)
  File "/opt/anaconda2/lib/python2.7/site-packages/werkzeug/serving.py", line 261, in execute
    write(data)
  File "/opt/anaconda2/lib/python2.7/site-packages/werkzeug/serving.py", line 242, in write
    self.wfile.write(data)
IOError: [Errno 32] Broken pipe
2018-11-29-22-05-21
2018-11-29-22-07-28
2018-11-29-22-07-34
2018-11-29-22-14-11
2018-11-29-22-14-16
2018-11-29-22-14-20
2018-11-29-22-14-24
2018-11-29-22-14-30
2018-11-29-22-14-36
2018-11-29-22-14-41
107.92.121.189 - - [29/Nov/2018 22:26:03] "[37mGET /getFiles/1 HTTP/1.1[0m" 200 -
2018-11-29-22-05-21
2018-11-29-22-07-28
2018-11-29-22-07-34
2018-11-29-22-14-11
2018-11-29-22-14-16
2018-11-29-22-14-20
2018-11-29-22-14-24
2018-11-29-22-14-30
2018-11-29-22-14-36
2018-11-29-22-14-41
107.92.121.189 - - [29/Nov/2018 22:26:03] "[37mGET /getFiles/1 HTTP/1.1[0m" 200 -
Error on request:
Traceback (most recent call last):
  File "/opt/anaconda2/lib/python2.7/site-packages/werkzeug/serving.py", line 270, in run_wsgi
    execute(self.server.app)
  File "/opt/anaconda2/lib/python2.7/site-packages/werkzeug/serving.py", line 261, in execute
    write(data)
  File "/opt/anaconda2/lib/python2.7/site-packages/werkzeug/serving.py", line 242, in write
    self.wfile.write(data)
IOError: [Errno 32] Broken pipe
Error on request:
Traceback (most recent call last):
  File "/opt/anaconda2/lib/python2.7/site-packages/werkzeug/serving.py", line 270, in run_wsgi
    execute(self.server.app)
  File "/opt/anaconda2/lib/python2.7/site-packages/werkzeug/serving.py", line 261, in execute
    write(data)
  File "/opt/anaconda2/lib/python2.7/site-packages/werkzeug/serving.py", line 242, in write
    self.wfile.write(data)
IOError: [Errno 104] Connection reset by peer
Error on request:
Traceback (most recent call last):
  File "/opt/anaconda2/lib/python2.7/site-packages/werkzeug/serving.py", line 270, in run_wsgi
    execute(self.server.app)
  File "/opt/anaconda2/lib/python2.7/site-packages/werkzeug/serving.py", line 261, in execute
    write(data)
  File "/opt/anaconda2/lib/python2.7/site-packages/werkzeug/serving.py", line 242, in write
    self.wfile.write(data)
IOError: [Errno 104] Connection reset by peer
Error on request:
Traceback (most recent call last):
  File "/opt/anaconda2/lib/python2.7/site-packages/werkzeug/serving.py", line 270, in run_wsgi
    execute(self.server.app)
  File "/opt/anaconda2/lib/python2.7/site-packages/werkzeug/serving.py", line 261, in execute
    write(data)
  File "/opt/anaconda2/lib/python2.7/site-packages/werkzeug/serving.py", line 242, in write
    self.wfile.write(data)
IOError: [Errno 104] Connection reset by peer
 * Detected change in '/home/ubuntu/builds/CEG4110-Project/database_controller.py', reloading
 * Restarting with stat
/opt/anaconda2/lib/python2.7/site-packages/h5py/__init__.py:36: FutureWarning: Conversion of the second argument of issubdtype from `float` to `np.floating` is deprecated. In future, it will be treated as `np.float64 == np.dtype(float).type`.
  from ._conv import register_converters as _register_converters
 * Debugger is active!
 * Debugger PIN: 331-445-009
